Time slot   0
ld_routine
Time slot   1
        Loaded a process at input/proc/p0s, PID: 1 PRIO: 130
        CPU 3: Dispatched process  1
Memop code: 872423872
Time slot   2
        Loaded a process at input/proc/s3, PID: 2 PRIO: 39
        CPU 3: Put process  1 to run queue
        CPU 2: Dispatched process  2
        CPU 3: Dispatched process  1
Memop code: 872423872
Time slot   3
Time slot   4
        Loaded a process at input/proc/m1s, PID: 3 PRIO: 15
        CPU 3: Put process  1 to run queue
        CPU 1: Dispatched process  3
Memop code: 872567888
        CPU 2: Put process  2 to run queue
Time slot   5
        CPU 2: Dispatched process  2
        CPU 3: Dispatched process  1
Memop code: 872423872
Time slot   6
Memop code: 872567888
        Loaded a process at input/proc/s2, PID: 4 PRIO: 120
write region=1 offset=20 value=100
print_pgtbl: 0 - 0
        CPU 0: Dispatched process  4
        CPU 3: Put process  1 to run queue
        CPU 3: Dispatched process  1
        CPU 2: Put process  2 to run queue
        CPU 2: Dispatched process  2
        CPU 1: Put process  3 to run queue
        CPU 1: Dispatched process  3
read region=1 offset=20 value=100
print_pgtbl: 0 - 0
Time slot   7
        Loaded a process at input/proc/m0s, PID: 5 PRIO: 120
write region=2 offset=20 value=102
Memop code: 872567888
print_pgtbl: 0 - 0
Time slot   8
        CPU 0: Put process  4 to run queue
        CPU 0: Dispatched process  4
Time slot   9
        CPU 3: Put process  1 to run queue
        Loaded a process at input/proc/p1s, PID: 6 PRIO: 15
        CPU 3: Dispatched process  1
read region=2 offset=20 value=102
print_pgtbl: 0 - 0
        CPU 1: Put process  3 to run queue
        CPU 1: Dispatched process  5
Memop code: 872711920
        CPU 2: Put process  2 to run queue
        CPU 2: Dispatched process  2
write region=3 offset=20 value=103
        CPU 0: Put process  4 to run queue
        CPU 0: Dispatched process  4
Memop code: 872711920
print_pgtbl: 0 - 0
Time slot  10
        CPU 2: Put process  2 to run queue
        CPU 2: Dispatched process  2
Time slot  11
        Loaded a process at input/proc/s0, PID: 7 PRIO: 38
        CPU 3: Put process  1 to run queue
        CPU 3: Dispatched process  1
read region=3 offset=20 value=103
print_pgtbl: 0 - 0
        CPU 1: Put process  5 to run queue
        CPU 1: Dispatched process  5
Time slot  12
Memop code: 872711920
        CPU 0: Put process  4 to run queue
        CPU 0: Dispatched process  4
        CPU 3: Put process  1 to run queue
        CPU 3: Dispatched process  1
Time slot  13
        CPU 2: Put process  2 to run queue
        CPU 2: Dispatched process  2
        CPU 1: Put process  5 to run queue
        CPU 1: Dispatched process  5
write region=1 offset=20 value=102
print_pgtbl: 0 - 0
        CPU 2: Processed  2 has finished
write region=2 offset=1000 value=1
print_pgtbl: 0 - 0
Time slot  14
        CPU 0: Put process  4 to run queue
        CPU 0: Dispatched process  4
        CPU 2: Dispatched process  7
        CPU 3: Processed  1 has finished
        CPU 3: Dispatched process  6
        CPU 1: Processed  5 has finished
        CPU 1: Dispatched process  3
Time slot  15
        Loaded a process at input/proc/s1, PID: 8 PRIO: 0
        CPU 0: Put process  4 to run queue
        CPU 0: Dispatched process  4
        CPU 2: Put process  7 to run queue
        CPU 2: Dispatched process  7
Time slot  16
        CPU 3: Put process  6 to run queue
Time slot  17
        CPU 3: Dispatched process  6
        CPU 1: Processed  3 has finished
        CPU 1: Dispatched process  8
Time slot  18
        CPU 0: Processed  4 has finished
        CPU 2: Put process  7 to run queue
        CPU 2: Dispatched process  7
        CPU 0 stopped
        CPU 3: Put process  6 to run queue
        CPU 1: Put process  8 to run queue
        CPU 1: Dispatched process  8
Time slot  19
        CPU 3: Dispatched process  6
Time slot  20
        CPU 2: Put process  7 to run queue
        CPU 2: Dispatched process  7
        CPU 3: Put process  6 to run queue
        CPU 1: Put process  8 to run queue
Time slot  21
        CPU 3: Dispatched process  6
        CPU 1: Dispatched process  8
Time slot  22
        CPU 2: Put process  7 to run queue
        CPU 2: Dispatched process  7
Time slot  23
        CPU 3: Put process  6 to run queue
        CPU 3: Dispatched process  6
        CPU 1: Put process  8 to run queue
        CPU 1: Dispatched process  8
Time slot  24
        CPU 1: Processed  8 has finished
        CPU 1 stopped
        CPU 2: Put process  7 to run queue
        CPU 2: Dispatched process  7
Time slot  25
        CPU 3: Processed  6 has finished
        CPU 3 stopped
Time slot  26
        CPU 2: Put process  7 to run queue
        CPU 2: Dispatched process  7
Time slot  27
Time slot  28
        CPU 2: Put process  7 to run queue
        CPU 2: Dispatched process  7
Time slot  29
        CPU 2: Processed  7 has finished
        CPU 2 stopped